Workbook
Name _Toc114998263: '1'!#REF!

Sheet Титул
A1: ФЕДЕРАЛЬНАЯ СЛУЖБА ГОСУДАРСТВЕННОЙ СТАТИСТИКИ
A3: УПРАВЛЕНИЕ ФЕДЕРАЛЬНОЙ СЛУЖБЫ ГОСУДАРСТВЕННОЙ СТАТИСТИКИ
A4: ПО ТЮМЕНСКОЙ ОБЛАСТИ,
A5: ХАНТЫ-МАНСИЙСКОМУ АВТОНОМНОМУ ОКРУГУ – ЮГРЕ
A6: И ЯМАЛО-НЕНЕЦКОМУ АВТОНОМНОМУ ОКРУГУ
A7: (ТЮМЕНЬСТАТ)
A20: Cоциально-экономическое положение
A21: Тюменской области (кроме Ханты-Мансийского автономного округа – Югры и Ямало-Ненецкого автономного округа)
A22: в январе-августе 2025 года
A24: КРАТКИЙ
A25: СТАТИСТИЧЕСКИЙ ДОКЛАД
A30: 25007
A41: Тюмень
A42: 2025

Sheet Ред.коллегия
A1: Редакционная коллегия:
A3: Л.О. Сараева – Председатель редакционной коллегии
A4: Ю.А. Карявина, Т.Л. Тихомирова, Л.Б. Савенкова, И.Г. Клепова
A9: Социально-экономическое положение Тюменской области (кроме Ханты-Мансийского автономного округа – Югры и Ямало-Ненецкого автономного округа) в январе-августе 2025 года: краткий стат. доклад/ Управление Федеральной службы государственной статистики по Тюменской области, Ханты-Мансийскому автономному округу – Югре и Ямало-Ненецкому автономному округу. – Т., 2025
A22: В кратком статистическом докладе помещены сведения о социально-экономическом положении Тюменской области (кроме Ханты-Мансийского автономного округа – Югры и Ямало-Ненецкого автономного округа) за отчетный период и нарастающим итогом с начала года в сравнении с соответствующим периодом предыдущего года. Предназначен для органов государственного управления, научных, образовательных, предпринимательских, банковских учреждений и других заинтересованных пользователей.
A41: Управление Федеральной службы государственной статистики по Тюменской области, Ханты-Мансийскому автономному округу – Югре и Ямало-Ненецкому автономному округу, 2025
A42: e-mail:72@rosstat.gov.ru http://72.rosstat.gov.ru

Sheet Предисловие
A1: ПРЕДИСЛОВИЕ
A3: В кратком статистическом докладе публикуется информация по основным экономическим и социальным показателям, подготовленная на основе данных государственных статистических наблюдений месячной, квартальной и годовой периодичности, а также сведений, предоставленных другими субъектами официального статистического учета в установленной сфере деятельности.
A4: Доклад содержит информацию о производстве товаров и услуг, рынке товаров и услуг, ценах и тарифах, об уровне жизни населения, о занятости и безработице в Тюменской области (кроме Ханты-Мансийского автономного округа – Югры и Ямало-Ненецкого автономного округа) за отчетный период и нарастающим итогом с начала года в сравнении с соответствующим периодом предыдущего года.
A5: В ряде случаев предварительные данные в последующих выпусках доклада уточняются в соответствии с методиками сбора и обработки сведений. При расчете отдельных показателей используется экспертная оценка по официальной методологии Федеральной службы государственной статистики.
A6: В целях обеспечения конфиденциальности первичных статистических данных, полученных от организаций, в соответствии с Федеральным законом от 29 декабря 2007 г. № 282 – ФЗ «Об официальном статистическом учете и системе государственной статистики в Российской Федерации» (п.5, ст.4; п.1, ст.9) отдельные статистические данные являются конфиденциальными и публикации не подлежат.
A7: В отдельных случаях незначительные расхождения между итогом и суммой слагаемых объясняются округлением данных.
A8: В помощь пользователям публикуются методологические пояснения, содержащие определения используемых в материале статистических терминов (показателей).

Sheet Ответственные
A1: ОТВЕТСТВЕННЫЕ ЗА РАЗДЕЛЫ ДОКЛАДА
A3: Основные экономические и социальные показатели | B3: Савенкова Л.Б. | C3: ' | D3: 39-30-51
D4: (доб. 1285)
A5: Производство товаров и услуг | B5: Исакова О.В. | C5: ' | D5: 39-30-53
D6: (доб. 1220)
B7: Володкина М.А. | C7: ' | D7: 39-30-59
D8: (доб. 1093)
B9: Радаева Н.Ю. | C9: ' | D9: 39-30-57
D10: (доб. 1078)
B11: Штрек О.Я. | C11: ' | D11: 39-30-54
D12: (доб. 1118)
A13: Рынки товаров и услуг | B13: Штрек О.Я. | C13: ' | D13: 39-30-54
D14: (доб. 1118)
A15: Цены | B15: Менг Л.Н. | C15: ' | D15: 39-30-58
D16: (доб. 1151)
A17: Состоние платежей и расчетов в организациях | B17: Менг Л.Н. | C17: ' | D17: 39-30-58
D18: (доб. 1151)
A19: Уровень жизни населения | B19: Скрипникова В.И. | C19: ' | D19: 39-30-56
D20: (доб. 1108)
A21: Занятость и безработица | B21: Скрипникова В.И. | C21: ' | D21: 39-30-56
D22: (доб. 1108)
A23: Методологические пояснения | B23: Савенкова Л.Б. | C23: ' | D23: 39-30-51
D24: (доб. 1285)
A28: Сокращения
A30: г. | B30: год | C30: м3 | D30: кубический метр
A31: га | B31: гектар | C31: млн | D31: миллион
A32: Гкал | B32: гигакалория | C32: полул. | D32: полулитр
A33: км | B33: километр | C33: р | D33: раз
A34: кВт ч | B34: киловатт-час | C34: т-км | D34: тонно-километр
A35: кг | B35: килограмм | C35: тыс. | D35: тысяча
A36: м2 | B36: квадратный метр
A40: Условные обозначения
A42: … | B42: данные не отражены (не имеются, являются конфиденциальными);
A43: - | B43: явление отсутствует;
A44: 0 | B44: величина явления меньше единицы измерения.

Sheet Содержание
B2: СОДЕРЖАНИЕ
B4: ПРЕДИСЛОВИЕ
A5: 1 | B5: I. ОСНОВНЫЕ ЭКОНОМИЧЕСКИЕ И СОЦИАЛЬНЫЕ ПОКАЗАТЕЛИ
B6: II. ПРОИЗВОДСТВО ТОВАРОВ И УСЛУГ
B7: ПРОМЫШЛЕННОЕ ПРОИЗВОДСТВО
A8: 2 | B8: Динамика индекса промышленного производства
A9: 3 | B9: Индексы производства по отдельным видам экономической деятельности
A10: 4 | B10: Объем отгруженных товаров собственного производства, выполненных работ и услуг собственными силами по отдельным видам экономической деятельности
A11: 5 | B11: Производство основных видов продукции
B12: СЕЛЬСКОЕ ХОЗЯЙСТВО
A13: 6 | B13: ='6'!A3
A14: 7 | B14: ='7'!A1
A15: 8 | B15: ='8'!A1
A16: 9 | B16: Производство основных видов продукции животноводства в сельскохозяйственных организациях
B17: СТРОИТЕЛЬСТВО
A18: 10 | B18: ='10'!A3
A19: 11 | B19: ='11'!A1
B20: АВТОМОБИЛЬНЫЙ ТРАНСПОРТ
A21: 12 | B21: ='12'!A3
A22: 13 | B22: ='13'!A1
B23: III. РЫНКИ ТОВАРОВ И УСЛУГ
B24: РОЗНИЧНАЯ ТОРГОВЛЯ
A25: 14 | B25: ='14'!A5
A26: 15 | B26: ='15'!A1
A27: 16 | B27: ='16'!A1
B28: РЫНОК ПЛАТНЫХ УСЛУГ НАСЕЛЕНИЮ
A29: 17 | B29: ='17'!A3
A30: 18 | B30: ='18'!A1
B31: IV. ЦЕНЫ
B32: ИНДЕКСЫ ПОТРЕБИТЕЛЬСКИХ ЦЕН И ТАРИФОВ
A33: 19 | B33: ='19'!A5
A34: 20 | B34: ='20'!A1
A35: 21 | B35: ='21'!A1
A36: 22 | B36: ='22'!A1
A37: 23 | B37: ='23'!A1
A38: 24 | B38: ='24'!A1
A39: 25 | B39: ='25'!A1
A40: 26 | B40: ='26'!A1
B41: ИНДЕКСЫ ЦЕН И ТАРИФОВ ПРОИЗВОДИТЕЛЕЙ
A42: 27 | B42: ='27'!A3
...

Sheet 1
A1: I. ОСНОВНЫЕ ЭКОНОМИЧЕСКИЕ И СОЦИАЛЬНЫЕ ПОКАЗАТЕЛИ | B1: I. ОСНОВНЫЕ ЭКОНОМИЧЕСКИЕ И СОЦИАЛЬНЫЕ ПОКАЗАТЕЛИ | C1: I. ОСНОВНЫЕ ЭКОНОМИЧЕСКИЕ И СОЦИАЛЬНЫЕ ПОКАЗАТЕЛИ | D1: I. ОСНОВНЫЕ ЭКОНОМИЧЕСКИЕ И СОЦИАЛЬНЫЕ ПОКАЗАТЕЛИ | E1: I. ОСНОВНЫЕ ЭКОНОМИЧЕСКИЕ И СОЦИАЛЬНЫЕ ПОКАЗАТЕЛИ | F1: I. ОСНОВНЫЕ ЭКОНОМИЧЕСКИЕ И СОЦИАЛЬНЫЕ ПОКАЗАТЕЛИ
B3: Август 2025 г. | C3: В % к соответствующему месяцу предыдущего года | D3: Январь-август 2025 г. | E3: В % к соответствующему периоду предыдущего года | F3: Справочно
B4: Август 2025 г. | C4: В % к соответствующему месяцу предыдущего года | D4: Январь-август 2025 г. | E4: В % к соответствующему периоду предыдущего года | F4: январь-август 2024 г. в % к январю-августу 2023 г.
A5: Индекс промышленного производства1) | C5: 98.5 | E5: 97.7 | F5: 100.9
A6: Объем работ, выполненных по виду экономической деятельности «строительство», млн рублей | B6: 25744.5 | C6: 118.2 | D6: 175279.3 | E6: 129.9 | F6: 82.4
A7: Ввод в действие жилых домов (с учетом жилых домов, построенных на земельных участках, предназначенных для ведения гражданами садоводства), м2 общей площади жилых помещений | B7: 194852 | C7: 101.9 | D7: 1538724 | E7: 90.1 | F7: 119
A8: Грузооборот автомобильного транспорта организаций (без субъектов малого предпринимательства), млн т-км | B8: 180.8 | C8: 99.3 | D8: 1383.2 | E8: 116.8 | F8: 113
A9: Оборот розничной торговли, млн рублей | B9: 61894.6 | C9: 103.6 | D9: 465118.2 | E9: 102 | F9: 114.2
A10: Объем платных услуг населению, млн рублей | B10: 19929.7 | C10: 101.9 | D10: 150317.2 | E10: 104.8 | F10: 106.5
A11: Индекс потребительских цен и тарифов на конец периода | C11: 108.36 | E11: 108.58 | F11: 106.8
A12: Индекс цен производителей промышленных товаров, реализованных на внутреннем рынке, на конец периода1) | C12: 84.6 | E12: 96.61 | F12: 114.34
A13: Индекс цен производителей сельскохозяйственной продукции, реализованной сельскохозяйственными организациями, на конец периода | C13: 104.74 | E13: 104.76 | F13: 110.82
A14: Сводный индекс цен на продукцию (затраты, услуги) инвестиционного назначения, на конец периода | C14: 108.4 | E14: 108.1 | F14: 108.1
A15: Индекс тарифов на грузовые перевозки, на конец периода | C15: 109.93 | E15: 109.9 | F15: 107.4
A16: Среднемесячная начисленная заработная плата одного работника2)
A17: номинальная, рублей | B17: 93419 | C17: 113.2 | D17: 90213 | E17: 111.8 | F17: 115.8
A18: реальная | C18: 103.8 | E18: 102.9 | F18: 108.6
A19: Численность официально зарегистрированных безработных на конец месяца, тыс. человек | B19: 2.5 | C19: 122.1
A21: 1) По видам экономической деятельности «добыча полезных ископаемых», «обрабатывающие производства», «обеспечение электрической энергией, газом и паром; кондиционирование воздуха», «водоснабжение; водоотведение, организация сбора и утилизации отходов, деятельность по ликвидации загрязнений» | B21: 1) По видам экономической деятельности «добыча полезных ископаемых», «обрабатывающие производства», «обеспечение электрической энергией, газом и паром; кондиционирование воздуха», «водоснабжение; водоотведение, организация сбора и утилизации отходов, деятельность по ликвидации загрязнений» | C21: 1) По видам экономической деятельности «добыча полезных ископаемых», «обрабатывающие производства», «обеспечение электрической энергией, газом и паром; кондиционирование воздуха», «водоснабжение; водоотведение, организация сбора и утилизации отходов, деятельность по ликвидации загрязнений» | D21: 1) По видам экономической деятельности «добыча полезных ископаемых», «обрабатывающие производства», «обеспечение электрической энергией, газом и паром; кондиционирование воздуха», «водоснабжение; водоотведение, организация сбора и утилизации отходов, деятельность по ликвидации загрязнений» | E21: 1) По видам экономической деятельности «добыча полезных ископаемых», «обрабатывающие производства», «обеспечение электрической энергией, газом и паром; кондиционирование воздуха», «водоснабжение; водоотведение, организация сбора и утилизации отходов, деятельность по ликвидации загрязнений» | F21: 1) По видам экономической деятельности «добыча полезных ископаемых», «обрабатывающие производства», «обеспечение электрической энергией, газом и паром; кондиционирование воздуха», «водоснабжение; водоотведение, организация сбора и утилизации отходов, деятельность по ликвидации загрязнений»
A22: 2)Абсолютные показатели за июль, январь-июль 2025 г., относительные – в % к июлю, январю-июлю 2024 г. и январю-июлю 2023 г. | B22: 2)Абсолютные показатели за июль, январь-июль 2025 г., относительные – в % к июлю, январю-июлю 2024 г. и январю-июлю 2023 г. | C22: 2)Абсолютные показатели за июль, январь-июль 2025 г., относительные – в % к июлю, январю-июлю 2024 г. и январю-июлю 2023 г. | D22: 2)Абсолютные показатели за июль, январь-июль 2025 г., относительные – в % к июлю, январю-июлю 2024 г. и январю-июлю 2023 г. | E22: 2)Абсолютные показатели за июль, январь-июль 2025 г., относительные – в % к июлю, январю-июлю 2024 г. и январю-июлю 2023 г. | F22: 2)Абсолютные показатели за июль, январь-июль 2025 г., относительные – в % к июлю, январю-июлю 2024 г. и январю-июлю 2023 г.

Sheet 2
A1: II. ПРОИЗВОДСТВО ТОВАРОВ И УСЛУГ
A3: ПРОМЫШЛЕННОЕ ПРОИЗВОДСТВО
A5: Динамика индекса промышленного производства1)
B7: В % к
B8: предыдущему месяцу | C8: соответствующему периоду предыдущего года
A9: 2025 г.
A10: Январь | B10: 94.6 | C10: 98
A11: Февраль | B11: 95.8 | C11: 95.3
A12: Март | B12: 110.1 | C12: 96.4
A13: Январь-март | C13: 96.5
A14: Апрель | B14: 90.2 | C14: 92.6
A15: Май | B15: 96.1 | C15: 91.1
A16: Июнь | B16: 101 | C16: 102.9
A17: Январь-июнь | C17: 95.9
A18: Июль | B18: 116.6 | C18: 107.5
A19: Август | B19: 100.4 | C19: 98.5
A20: Январь-август | C20: 97.7
A21: 2024 г.
A22: Январь | B22: 93.9 | C22: 102.6
A23: Февраль | B23: 98.5 | C23: 105.2
A24: Март | B24: 108.9 | C24: 101.8
A25: Январь-март | C25: 103.1
A26: Апрель | B26: 93.8 | C26: 102.2
A27: Май | B27: 97.7 | C27: 102.7
A28: Июнь | B28: 89.4 | C28: 92
A29: Январь-июнь | C29: 101.1
A30: Июль | B30: 111.6 | C30: 97.4
A31: Август | B31: 109.4 | C31: 103.4
A32: Сентябрь | B32: 94.1 | C32: 98.3
A33: Январь-сентябрь | C33: 100.6
A34: Октябрь | B34: 102.6 | C34: 96.1
A35: Ноябрь | B35: 93.1 | C35: 93.8
A36: Декабрь | B36: 107.3 | C36: 97.2
A37: Январь-декабрь | C37: 99.3
A39: 1) По видам экономической деятельности «добыча полезных ископаемых», «обрабатывающие производства», «обеспечение электрической энергией, газом и паром; кондиционирование воздуха», «водоснабжение; водоотведение, организация сбора и утилизации отходов, деятельность по ликвидации загрязнений»

Sheet 3
A1: Индексы производства по отдельным видам экономической деятельности
B3: Август 2025 г. в % к соответствующему месяцу предыдущего года | C3: Январь-август 2025 г. в % к соответствующему периоду предыдущего года
A4: Добыча полезных ископаемых | B4: 100.8 | C4: 100.4
A5: добыча прочих полезных ископаемых | B5: 105.4 | C5: 96.9
A6: предоставление услуг в области добычи полезных ископаемых | B6: 143.4 | C6: 139.6
A7: Обрабатывающие производства | B7: 98 | C7: 96.8
A8: производство пищевых продуктов | B8: 94.8 | C8: 95.4
A9: производство напитков | B9: 114.6 | C9: 105.5
A10: производство текстильных изделий | B10: 182.3 | C10: 98.9
A11: производство одежды | B11: 93.2 | C11: 100.2
A12: производство кожи и изделий из кожи | B12: 6,1р | C12: 95.2
A13: обработка древесины и производство изделий из дерева и пробки, кроме мебели, производство изделий из соломки и материалов для плетения | B13: 91.1 | C13: 97.1
A14: производство бумаги и бумажных изделий | B14: 81.1 | C14: 90.9
A15: деятельность полиграфическая и копирование носителей информации | B15: 93.1 | C15: 104.5
A16: производство кокса и нефтепродуктов | B16: 103 | C16: 100.8
A17: производство химических веществ и химических продуктов | B17: 96.3 | C17: 94.4
A18: производство лекарственных средств и материалов, применяемых в медицинских целях и ветеринарии | B18: 120.6 | C18: 104
A19: производство резиновых и пластмассовых изделий | B19: 94.7 | C19: 92.3
A20: производство прочей неметаллической минеральной продукции | B20: 96.5 | C20: 98.7
A21: производство металлургическое | B21: 99.9 | C21: 93.9
A22: производство готовых металлических изделий, кроме машин и оборудования | B22: 78.6 | C22: 80.2
A23: производство компьютеров, электронных и оптических изделий | B23: 90.3 | C23: 106.7
A24: производство электрического оборудования | B24: 86.9 | C24: 84.9
... A32: Водоснабжение; водоотведение, организация сбора и утилизации отходов, деятельность по ликвидации загрязнений | B32: 99.1 | C32: 91.6

Sheet 4
A1: Объем отгруженных товаров собственного производства, выполненных работ и услуг собственными силами по отдельным видам экономической деятельности
A3: в действующих ценах
B4: Август 2025 г. | D4: Январь-август 2025 г.
B5: млн рублей | C5: в % к соответству-ющему месяцу предыдущего года | D5: млн рублей | E5: в % к соответствующему периоду предыдущего года
A6: Добыча полезных ископаемых | B6: 23539.7 | C6: 75 | D6: 198354.2 | E6: 82.1
A7: добыча нефти и природного газа | B7: 20682.8 | C7: 71.6 | D7: 177670.2 | E7: 79
A8: добыча прочих полезных ископаемых | B8: 454.7 | C8: 118.5 | D8: 2378.1 | E8: 127.9
A9: предоставление услуг в области добычи полезных ископаемых | B9: 2402.2 | C9: 113.3 | D9: 18305.8 | E9: 122.6
A10: Обрабатывающие производства | B10: 106141.3 | C10: 87.2 | D10: 912087.2 | E10: 95.8
A11: производство пищевых продуктов | B11: 6287.5 | C11: 109.6 | D11: 49275.4 | E11: 108.3
A12: производство напитков | B12: 203.8 | C12: 121.6 | D12: 1824.5 | E12: 96.4
A13: производство текстильных изделий | B13: 21.6 | C13: 74.4 | D13: 220.3 | E13: 138.2
A14: производство одежды | B14: 17.4 | C14: 36.7 | D14: 231.9 | E14: 51.3
A15: производство кожи и изделий из кожи | B15: 2.3 | C15: 2,1р | D15: 11.5 | E15: 17.2
A16: обработка древесины и производство изделий из дерева и пробки, кроме мебели, производство изделий из соломки и материалов для плетения | B16: 415.4 | C16: 79.1 | D16: 3429.6 | E16: 114.8
A17: производство бумаги и бумажных изделий | B17: 307.8 | C17: 93.3 | D17: 3065.8 | E17: 101.5
A18: деятельность полиграфическая и копирование носителей информации | B18: 110.8 | C18: 125.9 | D18: 743.3 | E18: 127.5
A19: производство кокса и нефтепродуктов | B19: 44280.6 | C19: 100.1 | D19: 377424.5 | E19: 115.2
A20: производство химических веществ и химических продуктов | B20: 33868.1 | C20: 71 | D20: 285869 | E20: 71.5
A21: производство лекарственных средств и материалов, применяемых в медицинских целях и ветеринарии | B21: 752.4 | C21: 100.6 | D21: 7375.5 | E21: 125.2
A22: производство резиновых и пластмассовых изделий | B22: 4900.7 | C22: 82.7 | D22: 41320.8 | E22: 95.4
A23: производство прочей неметаллической минеральной продукции | B23: 3549.3 | C23: 104.5 | D23: 26352.3 | E23: 104.8
A24: производство металлургическое | B24: 3130 | C24: 88.3 | D24: 22583.1 | E24: 84.8
A25: производство готовых металлических изделий, кроме машин и оборудования | B25: 2386.9 | C25: 105.5 | D25: 20464.1 | E25: 106.9
A26: производство компьютеров, электронных и оптических изделий | B26: 136.6 | C26: 79.8 | D26: 2155.1 | E26: 102.3
A27: производство электрического оборудования | B27: 1461.7 | C27: 87.3 | D27: 10665 | E27: 84.4
A28: производство машин и оборудования, не включенных в другие группировки | B28: 1626.8 | C28: 68.9 | D28: 36060.5 | E28: 2,2р
A29: производство автотранспортных средств, прицепов и полуприцепов | B29: 367.8 | C29: 40.7 | D29: 4148.6 | E29: 76.7
A30: производство прочих транспортных средств и оборудования | B30: 305 | C30: 5,9р | D30: 743.5 | E30: 2р
A31: производство мебели | B31: 167.2 | C31: 116.7 | D31: 1288.7 | E31: 106.9
A32: производство прочих готовых изделий | B32: 166.1 | C32: 149.8 | D32: 1126 | E32: 148.9
A33: ремонт и монтаж машин и оборудования | B33: 1675.6 | C33: 106.1 | D33: 15708.4 | E33: 140.2
A34: Обеспечение электрической энергией, газом и паром; кондиционирование воздуха | B34: 5174.5 | C34: 130 | D34: 56232 | E34: 122.5
A35: Водоснабжение; водоотведение, организация сбора и утилизации отходов, деятельность по ликвидации загрязнений | B35: 3024.7 | C35: 97.5 | D35: 19764.2 | E35: 92.7

Sheet 5
A1: Производство основных видов продукции
B3: Август 2025 г. | C3: В % к | E3: Январь-август 2025 г. | F3: В % к соответст-вующему периоду преды-дущего года
C4: предыдущему месяцу | D4: соответст-вующему месяцу преды-дущего года
A5: Добыча полезных ископаемых
A6: Добыча нефти и природного газа
A7: газ нефтяной попутный (газ горючий природный нефтяных месторождений), млн м3 | B7: 27 | C7: 118.8 | D7: 109.5 | E7: 179 | F7: 89
A8: Добыча прочих полезных ископаемых
A9: пески природные, тыс. м3 | B9: 1398.6 | C9: 181.5 | D9: 106.3 | E9: 4902.1 | F9: 99.4
A10: Обрабатывающие производства
A11: Производство пищевых продуктов
A12: говядина, кроме субпродуктов, тонн | B12: 311.9 | C12: 108.2 | D12: 87.1 | E12: 2472 | F12: 91.9
A13: свинина, кроме субпродуктов, тонн | B13: 2518.7 | C13: 97.9 | D13: 103.1 | E13: 18815.8 | F13: 98.8
A14: мясо и субпродукты пищевые домашней птицы, тонн | B14: 7081.7 | C14: 104.2 | D14: 93.6 | E14: 55020.5 | F14: 96.9
A15: полуфабрикаты мясные, мясосодержащие, охлажденные, замороженные, тонн | B15: 5737.1 | C15: 103.1 | D15: 93 | E15: 45110.7 | F15: 98.2
A16: изделия колбасные, включая изделия колбасные для детского питания, тонн | B16: 866.4 | C16: 85.3 | D16: 99.6 | E16: 7259.9 | F16: 101.2
A17: рыба переработанная и консервированная, ракообразные и моллюски, тонн | B17: 87.3 | C17: 83.5 | D17: 92.1 | E17: 1185.1 | F17: 85.8
A18: молоко жидкое обработанное, включая молоко для детского питания, тонн | B18: 10812.7 | C18: 112.4 | D18: 107.6 | E18: 82132.8 | F18: 98.4
A19: сливки, тонн | B19: 471.8 | C19: 85.9 | D19: 47.6 | E19: 5265.2 | F19: 56
A20: масло сливочное, в том числе с пищевкусовыми компонентами, тонн | B20: 83.6 | C20: 77.3 | D20: 62.7 | E20: 677.8 | F20: 90
A21: сыры, тонн | B21: 131.2 | C21: 101.4 | D21: 100.2 | E21: 785.6 | F21: 95.6
A22: творог, тонн | B22: 1099.4 | C22: 104.3 | D22: 106 | E22: 9359.5 | F22: 108.1
A23: продукты кисломолочные (кроме творога и продуктов из творога), тонн | B23: 3206.3 | C23: 99.7 | D23: 100.8 | E23: 26507 | F23: 93.6
... A25: кондитерские изделия, тонн | B25: 1619.9 | C25: 108.2 | D25: 117.5 | E25: 12148.3 | F25: 109.3
A26: Производство напитков
A27: воды минеральные природные упакованные, воды питьевые упакованные, не содержащие сахара, подсластителей, ароматизаторов и других пищевых веществ, тыс. полул. | B27: 11480 | C27: 93.2 | D27: 105.1 | E27: 91729 | F27: 98.2
A28: Производство одежды
A29: спецодежда, тыс. штук | B29: 335.2 | C29: 107.4 | D29: 99.1 | E29: 2847.2 | F29: 100
A30: Производство кожи и изделий из кожи
A31: обувь, тыс. пар | B31: 1.7 | C31: 2,7р | D31: … | E31: 4.4 | F31: 95
A32: Обработка древесины и производство изделий из дерева и пробки, кроме мебели, производство изделий из соломки и материалов для плетения
A33: лесоматериалы, продольно распиленные или расколотые, разделенные на слои или лущеные, толщиной более 6 мм; деревянные железнодорожные или трамвайные шпалы, непропитанные, тыс. м3 | B33: 16.6 | C33: 105.3 | D33: 95.1 | E33: 119.4 | F33: 100.9
A34: фанера, м3 | B34: ... | C34: 69.3 | D34: 66.3 | E34: ... | F34: 94.5
A35: двери, их коробки и пороги деревянные, тыс. м2 | B35: 30 | C35: … | D35: 99.9 | E35: 177 | F35: 100
A36: Производство химических веществ и химических продуктов
A37: пластмассы в первичных формах, тонн | B37: 241449.2 | C37: 101.4 | D37: 99.8 | E37: 1722688 | F37: 97.4
A38: Производство лекарственных средств и материалов, применяемых в медицинских целях и ветеринарии
A39: препараты лекарственные, тыс. рублей | B39: ... | C39: 107.2 | D39: 114.8 | E39: ... | F39: 105.1
A40: Производство резиновых и пластмассовых изделий
A41: трубы, трубки и шланги и их фитинги пластмассовые, тонн | B41: 2250.3 | C41: 94 | D41: 80.6 | E41: 16374.7 | F41: 85.1
A42: Производство прочей неметаллической минеральной продукции
...

Sheet 6
A1: СЕЛЬСКОЕ ХОЗЯЙСТВО
A3: Валовые сборы основных сельскохозяйственных культур в хозяйствах всех категорий
B5: На 1 сентября 2025 г. | D5: Справочно на 1 сентября 2024 г.
B7: тыс. центнеров | C7: в % к соответствующему периоду предыдущего года | D7: тыс. центнеров | E7: в % к соответствующему периоду предыдущего года
A8: Зерновые и зернобобовые культуры (в первоначально-оприходованном весе) | B8: 4543.1 | C8: 137.1 | D8: 3312.6 | E8: 71.2
A9: Картофель | B9: 386.2 | C9: 103.9 | D9: 371.9 | E9: 91.4
A10: Овощи открытого и закрытого грунта | B10: 476 | C10: 101.7 | D10: 467.8 | E10: 126.3

Sheet 7
A1: Уборка зерновых и зернобобовых культур сельскохозяйственными организациями
B3: На 1 сентября 2025 г. | C3: Справочно на 1 сентября 2024 г.
A4: Скошено зерновых и зернобобовых культур
A5: тыс. гектаров | B5: 137.3 | C5: 113
A6: в % к площади посева | B6: 26.6 | C6: 19.8
A7: Обмолочено зерновых и зернобобовых культур
A8: тыс. гектаров | B8: 134.9 | C8: 113
A9: в % к площади посева | B9: 26.2 | C9: 19.8
A10: в % к скошенной площади | B10: 98.3 | C10: 100
A11: Намолочено зерна (в первоначально-оприходованном весе)
A12: всего, тыс. центнеров | B12: 3834.4 | C12: 2602.8
A13: с 1 га, центнеров | B13: 27.9 | C13: 23
A14: в том числе пшеницы
A15: всего, тыс. центнеров | B15: 914.9 | C15: 549.5
A16: с 1 га, центнеров | B16: 25.8 | C16: 22

Sheet 8
A1: Динамика поголовья основных видов скота в сельскохозяйственных организациях
A3: на конец месяца, в процентах к соответствующей дате предыдущего года
B4: Крупный рогатый скот | C4: Из него коровы | D4: Свиньи | E4: Овцы и козы | F4: Птица
A5: 2025 г.
A6: Январь | B6: 91.6 | C6: 92.9 | D6: 96.6 | E6: 116.6 | F6: 103.6
A7: Февраль | B7: 91.4 | C7: 92.8 | D7: 98.2 | E7: 130.9 | F7: 103
A8: Март | B8: 92 | C8: 93.2 | D8: 98.5 | E8: 140.9 | F8: 101.1
A9: Апрель | B9: 94 | C9: 94.5 | D9: 97.1 | E9: 146.6 | F9: 101.4
A10: Май | B10: 94.8 | C10: 95.3 | D10: 98.5 | E10: 153.4 | F10: 100.5
A11: Июнь | B11: 95.5 | C11: 96.5 | D11: 96.3 | E11: 169.3 | F11: 100.3
A12: Июль | B12: 96.4 | C12: 97.2 | D12: 97.8 | E12: 186.2 | F12: 99.6
A13: Август | B13: 97.6 | C13: 98.8 | D13: 98.4 | E13: 195.6 | F13: 101.3
A14: 2024 г.
A15: Январь | B15: 96.3 | C15: 96.6 | D15: 97.3 | E15: 2,9р | F15: 106.5
A16: Февраль | B16: 94.6 | C16: 95.4 | D16: 95.3 | E16: 2,9р | F16: 106.7
A17: Март | B17: 93.3 | C17: 95.2 | D17: 97.2 | E17: 2,8р | F17: 105.3
A18: Апрель | B18: 92 | C18: 94.8 | D18: 96.9 | E18: 2,6р | F18: 108.4
A19: Май | B19: 91.9 | C19: 95 | D19: 95.9 | E19: 2,2р | F19: 111.7
A20: Июнь | B20: 92.1 | C20: 94.1 | D20: 100.1 | E20: 199.9 | F20: 117.1
A21: Июль | B21: 91.3 | C21: 92.8 | D21: 102.1 | E21: 161.9 | F21: 114.7
A22: Август | B22: 90.8 | C22: 91.8 | D22: 101.3 | E22: 142.7 | F22: 108.3
A23: Сентябрь | B23: 91.1 | C23: 92.2 | D23: 100.2 | E23: 169.7 | F23: 109.2
A24: Октябрь | B24: 90.3 | C24: 91.5 | D24: 97.9 | E24: 151.7 | F24: 102.6
A25: Ноябрь | B25: 90.2 | C25: 91.1 | D25: 98.1 | E25: 139.1 | F25: 100.9
A26: Декабрь | B26: 92.2 | C26: 92.1 | D26: 96.6 | E26: 114.2 | F26: 100.4

Sheet 9
A1: Производство основных видов продукции животноводства в сельскохозяйственных организациях1)
B3: Август 2025 г. | D3: Январь-август 2025 г. в % к соответствующему периоду предыдущего года | E3: Справочно
B4: тыс. тонн | C4: в % к соответствующему месяцу предыдущего года | E4: январь-август 2024 г. в % к январю-августу 2023 г.
A5: Скот и птица на убой (в живом весе) – всего | B5: 13.7 | C5: 91 | D5: 93.3 | E5: 101.2
A6: в том числе:
A7: крупный рогатый скот | B7: 1.1 | C7: 85.9 | D7: 81.7 | E7: 107.4
A8: свиньи | B8: … | C8: … | D8: 96.7 | E8: 96.1
A9: птица | B9: … | C9: 89.7 | D9: 94 | E9: 102.2
A10: другие виды скота | B10: … | C10: 70.4 | D10: 2,5р | E10: 36.7
A11: Молоко | B11: 31 | C11: 99.3 | D11: 98.1 | E11: 100.3
A12: Яйца, млн штук | B12: 108.2 | C12: 114.2 | D12: 113.7 | E12: 97.6
A13: 1) С досчетом на микропредприятия
A15: Надои молока на одну корову в сельскохозяйственных организациях (без субъектов малого предпринимательства) в январе-августе 2025 г. составили 6148 килограммов (в январе-августе 2024 г. – 6007 килограммов), яйценоскость кур-несушек – 221 яйцо (228 яиц).

Sheet 10
A1: СТРОИТЕЛЬСТВО
A3: Объем работ, выполненных по виду экономической деятельности «строительство»
B5: Млн рублей | C5: В % к соответствующему периоду предыдущего года
A6: 2025 г.
A7: Январь-март | B7: 45781.4 | C7: 153.1
A8: Январь-июнь | B8: 118599.1 | C8: 131.1
A9: Январь-август | B9: 175279.3 | C9: 129.9
A10: 2024 г.
A11: Январь-март | B11: 27841.8 | C11: 73.7
A12: Январь-июнь | B12: 84336.9 | C12: 85.5
A13: Январь-сентябрь | B13: 146529.3 | C13: 84.4
A14: Январь-декабрь | B14: 220274.7 | C14: 92.3

Sheet 11
A1: Динамика ввода в действие жилых домов (с учетом жилых домов, построенных на земельных участках, предназначенных для ведения гражданами садоводства)
B3: Квадратных метров общей площади жилых помещений | C3: В % к
C4: предыдущему периоду | D4: соответствующему периоду предыдущего года
A5: 2025 г.
A6: Январь | B6: 256605 | C6: 76 | D6: 62.6
A7: Февраль | B7: 162216 | C7: 63.2 | D7: 91.1
A8: Март | B8: 287976 | C8: 177.5 | D8: 101.3
A9: I квартал | B9: 706797 | C9: 105.2 | D9: 81
A10: Апрель | B10: 111006 | C10: 38.5 | D10: 131.2
A11: Май | B11: 131536 | C11: 118.5 | D11: 76.3
A12: Июнь | B12: 239880 | C12: 182.4 | D12: 103
A13: II квартал | B13: 482422 | C13: 68.3 | D13: 98.4
A14: Январь-июнь | B14: 1189219 | D14: 87.3
A15: Июль | B15: 154653 | C15: 64.5 | D15: 100.6
A16: Август | B16: 194852 | C16: 126 | D16: 101.9
A17: Январь-август | B17: 1538724 | D17: 90.1
A18: 2024 г.
A19: Январь | B19: 410078 | C19: 94.7 | D19: 140.3
A20: Февраль | B20: 178109 | C20: 43.4 | D20: 91.9
A21: Март | B21: 284420 | C21: 159.7 | D21: 2,1р
A22: I квартал | B22: 872607 | C22: 105.9 | D22: 140.6
A23: Апрель | B23: 84599 | C23: 29.7 | D23: 88.6
A24: Май | B24: 172505 | C24: 2р | D24: 182.4
A25: Июнь | B25: 232916 | C25: 135 | D25: 134.9
A26: II квартал | B26: 490020 | C26: 56.2 | D26: 135.1
A27: Январь-июнь | B27: 1362627 | D27: 138.6
A28: Июль | B28: 153701 | C28: 66 | D28: 62.1
A29: Август | B29: 191132 | C29: 124.4 | D29: 93.6
A30: Сентябрь | B30: 224298 | C30: 117.4 | D30: 99.2
A31: III квартал | B31: 569131 | C31: 116.1 | D31: 84
A32: Январь-сентябрь | B32: 1931758 | D32: 116.3
A33: Октябрь | B33: 119356 | C33: 53.2 | D33: 56.3
A34: Ноябрь | B34: 214538 | C34: 179.7 | D34: 119.8
A35: Декабрь | B35: 337676 | C35: 157.4 | D35: 77.9
A36: IV квартал | B36: 671570 | C36: 118 | D36: 81.5
A37: Январь-декабрь | B37: 2603328 | D37: 104.7

Sheet 12
A1: АВТОМОБИЛЬНЫЙ ТРАНСПОРТ
A3: Динамика грузооборота автомобильного транспорта организаций (без субъектов малого предпринимательства) всех видов экономической деятельности
B5: Грузооборот, млн т-км | C5: В % к соответствующему месяцу предыдущего года
A6: 2025 г.
A7: Январь | B7: 140.8 | C7: 126.9
A8: Февраль | B8: 170.1 | C8: 136.7
A9: Март | B9: 191 | C9: 122.3
A10: Апрель | B10: 182.7 | C10: 124.3
A11: Май | B11: 173.6 | C11: 116.9
A12: Июнь | B12: 170.3 | C12: 110.7
A13: Июль | B13: 173.9 | C13: 107.6
A14: Август | B14: 180.8 | C14: 99.3
A15: 2024 г.
A16: Январь | B16: 111 | C16: 86.7
A17: Февраль | B17: 124.5 | C17: 108.8
A18: Март | B18: 156.2 | C18: 127.3
A19: Апрель | B19: 146.9 | C19: 114.1
A20: Май | B20: 148.5 | C20: 108.5
A21: Июнь | B21: 153.8 | C21: 111.7
A22: Июль | B22: 161.7 | C22: 120.8
A23: Август | B23: 182.1 | C23: 124.5
A24: Сентябрь | B24: 184.9 | C24: 128.4
A25: Октябрь | B25: 165.2 | C25: 111.1
A26: Ноябрь | B26: 157.9 | C26: 129.2
A27: Декабрь | B27: 162.9 | C27: 138.2

Sheet 13
A1: Динамика пассажирооборота автомобильного транспорта общего пользования (c учетом физических лиц, осуществляющих перевозки пассажиров на коммерческой основе)
B3: Пассажирооборот, млн пасс.-км | C3: В % к соответствующему месяцу предыдущего года
A4: 2025 г.
A5: Январь | B5: 104.5 | C5: 102.6
A6: Февраль | B6: 110.2 | C6: 99.8
A7: Март | B7: 120.3 | C7: 105.5
A8: Апрель | B8: 125.5 | C8: 106.4
A9: Май | B9: 126.2 | C9: 101.5
A10: Июнь | B10: 122 | C10: 102.8
A11: Июль1) | B11: 124.5 | C11: 101.1
A12: Август | B12: 119.6 | C12: 98.1
A13: 2024 г.
A14: Январь | B14: 101.9 | C14: 97.8
A15: Февраль | B15: 110.4 | C15: 104.1
A16: Март | B16: 114 | C16: 91.2
A17: Апрель | B17: 118 | C17: 95.9
A18: Май | B18: 124.3 | C18: 96.4
A19: Июнь | B19: 118.7 | C19: 98.4
A20: Июль | B20: 123.2 | C20: 102.2
A21: Август | B21: 122 | C21: 97.2
A22: Сентябрь | B22: 129.3 | C22: 100.6
A23: Октябрь | B23: 128.2 | C23: 97.7
A24: Ноябрь | B24: 121.1 | C24: 98.8
A25: Декабрь | B25: 120 | C25: 101.4
A27: 1) Уточнено

Sheet 14
A1: III. РЫНКИ ТОВАРОВ И УСЛУГ
A3: РОЗНИЧНАЯ ТОРГОВЛЯ
A5: Динамика оборота розничной торговли
B7: Млн рублей | C7: В % к
C8: предыдущему периоду | D8: соответствующему периоду предыдущего года
A9: 2025 г.
A10: Январь | B10: 53733.7 | C10: 82.5 | D10: 101.9
A11: Февраль | B11: 52433.5 | C11: 96.5 | D11: 97.4
A12: Март | B12: 57369.7 | C12: 108.6 | D12: 102.8
A13: I квартал | B13: 163536.9 | C13: 94 | D13: 100.7
A14: Апрель | B14: 57976.9 | C14: 100.8 | D14: 101.6
A15: Май | B15: 59012 | C15: 101.5 | D15: 101.7
A16: Июнь | B16: 61506.5 | C16: 104.3 | D16: 104
A17: II квартал | B17: 178495.4 | C17: 107.4 | D17: 102.4
A18: Январь-июнь | B18: 342032.4 | D18: 101.6
A19: Июль | B19: 61191.2 | C19: 99.6 | D19: 102.4
A20: Август | B20: 61894.6 | C20: 101.8 | D20: 103.6
A21: Январь-август | B21: 465118.2 | D21: 102
A22: 2024 г.
A23: Январь | B23: 49457.2 | C23: 88.5 | D23: 122.6
A24: Февраль | B24: 50197.1 | C24: 101 | D24: 120.8
A25: Март | B25: 51709 | C25: 102.9 | D25: 116
A26: I квартал | B26: 151363.2 | C26: 96.4 | D26: 118
A27: Апрель | B27: 53361.8 | C27: 102 | D27: 112.6
A28: Май | B28: 53613.4 | C28: 101.4 | D28: 112.8
A29: Июнь | B29: 54661.9 | C29: 101.9 | D29: 113.5
A30: II квартал | B30: 161637 | C30: 105.9 | D30: 113.2
A31: Январь-июнь | B31: 313000.2 | D31: 115.7
A32: Июль | B32: 55599 | C32: 101.1 | D32: 105.2
A33: Август | B33: 56000.3 | C33: 100.6 | D33: 103
A34: Сентябрь | B34: 55796.5 | C34: 99.3 | D34: 102.4
A35: III квартал | B35: 167395.8 | C35: 103.2 | D35: 103.5
A36: Январь-сентябрь | B36: 480396 | D36: 111.1
A37: Октябрь | B37: 57009.3 | C37: 101.2 | D37: 102.5
A38: Ноябрь | B38: 57954.1 | C38: 100.5 | D38: 105.9
A39: Декабрь | B39: 64539.3 | C39: 109.7 | D39: 109.7
A40: IV квартал | B40: 179502.7 | C40: 104.5 | D40: 109.1
A41: Январь-декабрь | B41: 659898.7 | D41: 109.8

Sheet 15
A1: Оборот розничной торговли торгующих организаций и продажа товаров на розничных рынках и ярмарках
B3: Август 2025 г. | D3: Январь-август 2025 г. | F3: Справочно
B4: млн рублей | C4: в % к соответствующему месяцу предыдущего года | D4: млн рублей | E4: в % к соответствующему периоду предыдущего года | F4: январь-август 2024 г. в % к январю-августу 2023 г.
A5: Всего | B5: 61894.6 | C5: 103.6 | D5: 465118.2 | E5: 102 | F5: 114.2
A6: в том числе:
A7: торгующих организаций и индивидуальных предпринимателей вне рынка | B7: 61557.9 | C7: 103.7 | D7: 462545.8 | E7: 102.1 | F7: 114.3
A8: продажа товаров на розничных рынках и ярмарках (без учета юридических лиц) | B8: 336.7 | C8: 83.6 | D8: 2572.3 | E8: 85.3 | F8: 98.5

Sheet 16
A1: Динамика оборота розничной торговли пищевыми продуктами, включая напитки, и табачными изделиями, непродовольственными товарами
B3: Пищевые продукты, включая напитки, и табачные изделия | E3: Непродовольственные товары
B4: млн рублей | C4: в % к | E4: млн рублей | F4: в % к
C5: предыду-щему периоду | D5: соответст-вующему периоду предыду-щего года | F5: предыду-щему периоду | G5: соответст-вующему периоду предыду-щего года
A6: 2025 г.
A7: Январь | B7: 26045 | C7: 83 | D7: 100.5 | E7: 27688.7 | F7: 82.2 | G7: 103.3
A8: Февраль | B8: 25342 | C8: 95.7 | D8: 95.9 | E8: 27091.5 | F8: 97.2 | G8: 98.9
A9: Март | B9: 27572 | C9: 107.5 | D9: 100.6 | E9: 29797.7 | F9: 109.8 | G9: 105
A10: I квартал | B10: 78959 | C10: 94 | D10: 99 | E10: 84577.9 | F10: 94.5 | G10: 102.4
A11: Апрель | B11: 27982.3 | C11: 100.4 | D11: 99.9 | E11: 29994.6 | F11: 101.2 | G11: 103.4
A12: Май | B12: 28613 | C12: 101.4 | D12: 99.5 | E12: 30399 | F12: 101.8 | G12: 104.2
A13: Июнь | B13: 29904.8 | C13: 104.6 | D13: 101.6 | E13: 31601.7 | F13: 104.1 | G13: 106.8
A14: II квартал | B14: 86500 | C14: 106.3 | D14: 100.4 | E14: 91995.4 | F14: 109.3 | G14: 104.8
A15: Январь-июнь | B15: 165459 | D15: 99.7 | E15: 176573.3 | G15: 103.6
A16: Июль | B16: 28974.8 | C16: 97.3 | D16: 98.9 | E16: 32216.4 | F16: 101.8 | G16: 106.3
A17: Август | B17: 29130.4 | C17: 102.2 | D17: 100.5 | E17: 32764.2 | F17: 101.2 | G17: 106.9
A18: Январь-август | B18: 223564.3 | D18: 99.7 | E18: 241553.9 | G18: 104.4
A19: 2024 г.
A20: Январь | B20: 23932.1 | C20: 88.2 | D20: 118 | E20: 25525.1 | F20: 89.3 | G20: 124.2
A21: Февраль | B21: 24332.1 | C21: 100.4 | D21: 117.4 | E21: 25865 | F21: 101.6 | G21: 124
A22: Март | B22: 24922.1 | C22: 102.4 | D22: 112.1 | E22: 26786.9 | F22: 103.3 | G22: 116.4
A23: I квартал | B23: 73186.2 | C23: 99.8 | D23: 115.7 | E23: 78177.1 | F23: 92.4 | G23: 121.4
A24: Апрель | B24: 25464.8 | C24: 101.1 | D24: 110.9 | E24: 27896.9 | F24: 102.8 | G24: 114.3
A25: Май | B25: 25560.2 | C25: 101.8 | D25: 111.4 | E25: 28053.1 | F25: 101 | G25: 114.3
A26: Июнь | B26: 26194.6 | C26: 102.4 | D26: 111.2 | E26: 28467.3 | F26: 101.6 | G26: 115.6
A27: II квартал | B27: 77219.7 | C27: 104.9 | D27: 111.3 | E27: 84417.3 | F27: 106.9 | G27: 114.7
A28: Январь-июнь | B28: 150405.8 | D28: 113.4 | E28: 162594.4 | G28: 117.9
A29: Июль | B29: 26133.6 | C29: 99.9 | D29: 103.5 | E29: 29465.4 | F29: 102.2 | G29: 106.7
A30: Август | B30: 26264.5 | C30: 100.6 | D30: 103.1 | E30: 29735.9 | F30: 100.6 | G30: 102.9
A31: Сентябрь | B31: 26826.3 | C31: 101.6 | D31: 104.8 | E31: 28970.2 | F31: 97.3 | G31: 100.4
A32: III квартал | B32: 79224.4 | C32: 103 | D32: 103.9 | E32: 88171.4 | F32: 103.1 | G32: 103.3
A33: Январь-сентябрь | B33: 229630.2 | D33: 109.9 | E33: 250765.8 | G33: 112.4
A34: Октябрь | B34: 27524.3 | C34: 101.7 | D34: 104.2 | E34: 29485 | F34: 100.7 | G34: 101
A35: Ноябрь | B35: 27524.3 | C35: 98 | D35: 104.6 | E35: 30429.8 | F35: 102.9 | G35: 107.1
A36: Декабрь | B36: 31004 | C36: 110 | D36: 107 | E36: 33535.3 | F36: 109.4 | G36: 112.3
A37: IV квартал | B37: 86052.6 | C37: 105 | D37: 105.4 | E37: 93450.1 | F37: 104.3 | G37: 106.8
A38: Январь-декабрь | B38: 315682.8 | D38: 108.6 | E38: 344215.9 | G38: 110.9

Sheet 17
A1: РЫНОК ПЛАТНЫХ УСЛУГ НАСЕЛЕНИЮ
A3: Динамика объема платных услуг населению
B5: Млн рублей | C5: В % к
C6: предыдущему периоду | D6: соответствующему периоду предыдущего года
A7: 2025 г.
A8: Январь | B8: 17329.8 | C8: 98.4 | D8: 105.5
A9: Февраль | B9: 18080.803 | C9: 103.4 | D9: 103.6
A10: Март | B10: 19020.902 | C10: 104.3 | D10: 109.5
A11: I квартал | B11: 54431.5 | C11: 104.5 | D11: 106.9
A12: Апрель | B12: 19048 | C12: 99 | D12: 107.9
A13: Май | B13: 18634.2 | C13: 97 | D13: 102.7
A14: Июнь | B14: 18923.9 | C14: 101.2 | D14: 104.8
A15: II квартал | B15: 56606.1 | C15: 101.3 | D15: 107.2
A16: Январь-июнь | B16: 111037.7 | D16: 106.1
A17: Июль1) | B17: 19349.8 | C17: 100.1 | D17: 100.6
A18: Август | B18: 19929.7 | C18: 103.2 | D18: 101.9
A19: Январь-август | B19: 150317.2 | D19: 104.8
A20: 2024 г.
A21: Январь | B21: 14802.5 | C21: 105.4 | D21: 104.4
A22: Февраль | B22: 15779.7 | C22: 104.8 | D22: 111.3
A23: Март | B23: 15849.5 | C23: 97.8 | D23: 98.1
A24: I квартал | B24: 46431.7 | C24: 110.5 | D24: 104.4
A25: Апрель | B25: 15759.6 | C25: 102.6 | D25: 104.6
A26: Май | B26: 16214 | C26: 101.9 | D26: 105.3
A27: Июнь | B27: 16549.9 | C27: 99.1 | D27: 102.9
A28: II квартал | B28: 48523.5 | C28: 103.3 | D28: 104.3
A29: Январь-июнь | B29: 94955.2 | D29: 104.3
A30: Июль | B30: 17501.5 | C30: 104.2 | D30: 115.3
A31: Август | B31: 17446.7 | C31: 102.1 | D31: 110.5
A32: Сентябрь | B32: 15996.5 | C32: 90.6 | D32: 113.9
A33: III квартал | B33: 50944.7 | C33: 102.1 | D33: 113.1
A34: Январь-сентябрь | B34: 145899.9 | D34: 107.2
A35: Октябрь | B35: 16507.1 | C35: 100.4 | D35: 112.4
A36: Ноябрь | B36: 16535.3 | C36: 99.3 | D36: 111.4
A37: Декабрь | B37: 17416.3 | C37: 105.9 | D37: 112.5
A38: IV квартал | B38: 50458.7 | C38: 96.1 | D38: 112.2
A39: Январь-декабрь | B39: 196358.6 | D39: 108.4
A41: 1) Уточнено

Sheet 18
A1: Объем платных услуг населению по видам
B3: Январь-август 2025 г., млн рублей | C3: В % к соответствующему периоду предыдущего года | D3: Справочно
D4: январь-август 2024 г. в % к январю-августу 2023 г.
A5: Всего | B5: 150317.2 | C5: 104.8 | D5: 106.5
A6: в том числе:
A7: бытовые | B7: 13249.4 | C7: 106.1 | D7: 118.9
A8: транспортные | B8: 28737.2 | C8: 101.7 | D8: 82.3
A9: почтовой связи, курьерские | B9: 1772.5 | C9: 114.1 | D9: 129.6
A10: из них
A11: услуги курьерской доставки | B11: 141.2 | C11: 116.5 | D11: 2,7р
A12: телекоммуникационные | B12: 14558.7 | C12: 97.1 | D12: 99.8
A13: жилищные | B13: 9520.6 | C13: 99.7 | D13: 111.7
A14: коммунальные | B14: 24760.5 | C14: 104.5 | D14: 103.4
A15: учреждений культуры | B15: 3054 | C15: 96.8 | D15: 106.8
A16: туристических агентств, туроператоров и прочие услуги по бронированию и сопутствующие им услуги | B16: 11452.6 | C16: 110 | D16: 161.6
A17: гостиниц и аналогичные услуги по предоставлению временного жилья | B17: 2658.9 | C17: 93.5 | D17: 112.4
A18: физической культуры и спорта | B18: 2273.5 | C18: 133.1 | D18: 141.8
A19: из них
A20: услуги фитнес-центров и спортивных клубов | B20: 1053.3 | C20: 110.2 | D20: 112.8
A21: медицинские | B21: 17127.6 | C21: 111.1 | D21: 134.9
A22: специализированных коллективных средств размещения | B22: 4545.8 | C22: 99.7 | D22: 101.2
A23: из них
A24: санаторно-курортных организаций | B24: 3833.5 | C24: 104.7 | D24: 95.4
A25: ветеринарные | B25: 754 | C25: 106.1 | D25: 136.4
A26: юридические | B26: 1002.1 | C26: 96 | D26: 109.7
A27: системы образования | B27: 8102.4 | C27: 99.9 | D27: 98.2
A28: услуги, предоставляемые гражданам пожилого возраста и инвалидам | B28: 620.7 | C28: 97.8 | D28: 90
A29: прочие виды | B29: 6126.7 | C29: 132.7 | D29: 124.1
A30: из них
A31: электронные услуги и сервисы в области информационно-коммуникационных технологий | B31: 658.3 | C31: 113 | D31: 177

Sheet 19
A1: IV. ЦЕНЫ
A3: ИНДЕКСЫ ПОТРЕБИТЕЛЬСКИХ ЦЕН И ТАРИФОВ
A5: Динамика индексов потребительских цен и тарифов на товары и услуги населению
A7: на конец периода, в процентах к предыдущему периоду
B8: Все товары и услуги | C8: В том числе на
C9: продоволь-ственные товары | D9: непродоволь-ственные товары | E9: услуги
A10: 2025 г.
A11: Январь | B11: 100.9 | C11: 101.3 | D11: 100.5 | E11: 100.9
A12: Февраль | B12: 101.1 | C12: 101.7 | D12: 100.6 | E12: 100.4
A13: Март | B13: 100.9 | C13: 101.2 | D13: 100.2 | E13: 101.1
A14: I квартал | B14: 103.1 | C14: 105.2 | D14: 101.6 | E14: 101.6
A15: Апрель | B15: 100.3 | C15: 101.1 | D15: 99.5 | E15: 100
A16: Май | B16: 100.7 | C16: 101 | D16: 99.7 | E16: 101.6
A17: Июнь | B17: 100.1 | C17: 100 | D17: 99.9 | E17: 100.5
A18: II квартал | B18: 101.7 | C18: 103.1 | D18: 99.5 | E18: 102.1
A19: Июль | B19: 100.9 | C19: 99.7 | D19: 100.2 | E19: 104.5
A20: Август | B20: 99.5 | C20: 98.5 | D20: 100.4 | E20: 100
A21: 2024 г.
A22: Январь | B22: 100.9 | C22: 100.8 | D22: 101.4 | E22: 100.5
A23: Февраль | B23: 100.7 | C23: 101.1 | D23: 99.9 | E23: 101.1
A24: Март | B24: 100.4 | C24: 100 | D24: 100.2 | E24: 101.5
A25: I квартал | B25: 102.9 | C25: 103.8 | D25: 102 | E25: 102.3
A26: Апрель | B26: 100.8 | C26: 101.1 | D26: 101.3 | E26: 99.6
A27: Май | B27: 99.5 | C27: 98.7 | D27: 99.6 | E27: 101
A28: Июнь | B28: 100.2 | C28: 100.1 | D28: 99.9 | E28: 100.9
A29: II квартал | B29: 101.1 | C29: 100.6 | D29: 101.1 | E29: 102
A30: Июль | B30: 101 | C30: 99.9 | D30: 101.3 | E30: 102.9
A31: Август | B31: 100.1 | C31: 99.9 | D31: 100.3 | E31: 100.2
A32: Сентябрь | B32: 100.5 | C32: 100.6 | D32: 100.1 | E32: 100.8
A33: III квартал | B33: 101.3 | C33: 99.6 | D33: 101.3 | E33: 104.3
... A37: IV квартал | B37: 102.5 | C37: 103.4 | D37: 101.6 | E37: 102.2

Sheet 20
A1: Индексы потребительских цен на отдельные группы и виды продовольственных товаров
A3: на конец месяца, в процентах
B4: Август 2025 г. к
B5: предыдущему месяцу | C5: декабрю 2024 г. | D5: соответствующему месяцу предыдущего года
A6: Продовольственные товары | B6: 98.5 | C6: 104.4 | D6: 110.6
A7: Продовольственные товары без алкогольных напитков | B7: 98.2 | C7: 103.7 | D7: 110.4
A8: Мясо и птица | B8: 100.3 | C8: 109 | D8: 113.1
A9: Колбасные изделия и продукты из мяса и птицы | B9: 100.9 | C9: 102 | D9: 106.1
A10: Рыба и морепродукты | B10: 97.4 | C10: 109.5 | D10: 117.6
A11: Масло сливочное | B11: 105.2 | C11: 99.8 | D11: 125.3
A12: Масло подсолнечное | B12: 100.4 | C12: 104 | D12: 114.7
A13: Молоко и молочная продукция | B13: 100.9 | C13: 105.2 | D13: 117.1
A14: Сыр | B14: 95.9 | C14: 100.8 | D14: 111
A15: Яйца куриные | B15: 100.6 | C15: 79.4 | D15: 87.8
A16: Сахар-песок | B16: 100.3 | C16: 101.5 | D16: 97.1
A17: Кондитерские изделия | B17: 99.2 | C17: 103.8 | D17: 110.8
... A22: Алкогольные напитки | B22: 100.3 | C22: 110.5 | D22: 112.3

Sheet 21
A1: Индексы потребительских цен на отдельные группы непродовольственных товаров
A3: на конец месяца, в процентах
B4: Август 2025 г. к
B5: предыдущему месяцу | C5: декабрю 2024 г. | D5: соответствующему месяцу предыдущего года
A6: Непродовольственные товары | B6: 100.4 | C6: 101 | D6: 103.1
A7: Одежда и белье | B7: 100.2 | C7: 99 | D7: 100.8
A8: Трикотажные изделия | B8: 100.2 | C8: 97.7 | D8: 97.8
A9: Ткани | B9: 99.9 | C9: 102.2 | D9: 102.1
A10: Обувь | B10: 100.8 | C10: 94.4 | D10: 94.5
A11: Табачные изделия | B11: 100.1 | C11: 104.4 | D11: 104.5
A12: Мебель | B12: 100 | C12: 101 | D12: 104.2
A13: Телерадиотовары | B13: 99.6 | C13: 86.2 | D13: 88.7
A14: Бензин автомобильный | B14: 100.7 | C14: 105.7 | D14: 110
A15: Медикаменты | B15: 100.1 | C15: 109.4 | D15: 113.6
A16: Моющие и чистящие средства | B16: 98.4 | C16: 99.6 | D16: 98.8
A17: Электротовары и другие бытовые приборы | B17: 101.4 | C17: 93.2 | D17: 100.8
... A19: Легковые автомобили | B19: 100.1 | C19: 101.1 | D19: 101.9

Sheet 22
A1: Индексы потребительских цен и тарифов на отдельные группы услуг
A3: на конец месяца, в процентах
B4: Август 2025 г. к
B5: предыдущему месяцу | C5: декабрю 2024 г. | D5: соответствующему месяцу предыдущего года
A6: Услуги | B6: 100 | C6: 109.2 | D6: 112
A7: Бытовые услуги | B7: 100.5 | C7: 108.5 | D7: 111.1
A8: Услуги пассажирского транспорта | B8: 98.3 | C8: 108 | D8: 113.3
A9: Услуги почтовой связи | B9: 100.6 | C9: 99.9 | D9: 106.1
A10: Услуги телекоммуникационные | B10: 98.2 | C10: 98.1 | D10: 107.9
A11: Жилищные и коммунальные услуги (включая аренду квартир) | B11: 100.7 | C11: 113.7 | D11: 112.4
A12: Услуги дошкольного воспитания | B12: 100 | C12: 101.2 | D12: 112.2
A13: Услуги гостиниц и прочих мест проживания | B13: 102.5 | C13: 106.1 | D13: 109.3
A14: Услуги образования | B14: 100.6 | C14: 102.6 | D14: 109
A15: Услуги организаций культуры | B15: 101.6 | C15: 104.9 | D15: 114.9
A16: Услуги зарубежного туризма | B16: 100.7 | C16: 112.2 | D16: 103.3
A17: Санаторно-оздоровительные услуги | B17: 100.7 | C17: 108.2 | D17: 111.5
... A21: Услуги физической культуры и спорта | B21: 100.9 | C21: 104.5 | D21: 107

Sheet 23
A1: Индексы цен на жилищные и коммунальные услуги
A3: на конец месяца, в процентах
B4: Август 2025 г. к
B5: предыдущему месяцу | C5: декабрю 2024 г. | D5: соответствующему месяцу предыдущего года
A6: Жилищные услуги (без аренды квартир у частных лиц) | B6: 100.5 | C6: 121.3 | D6: 122.7
A7: оплата жилья в домах государственного и муниципального жилищных фондов | B7: 100 | C7: 104.4 | D7: 105.1
A8: содержание, ремонт жилья для граждан-собственников жилья | B8: 100 | C8: 106.8 | D8: 107.9
A9: услуги по организации и выполнению работ по эксплуатации домов ЖК, ЖСК, ТСЖ | B9: 103.1 | C9: 105.8 | D9: 112
A10: взносы на капитальный ремонт | B10: 100 | C10: 146.2 | D10: 146.2
A11: Коммунальные услуги | B11: 100 | C11: 114.8 | D11: 114.8
A12: обращение с твердыми коммунальными отходами | B12: 100 | C12: 111.4 | D12: 111.4
A13: водоснабжение холодное | B13: 100 | C13: 111.3 | D13: 111.3
A14: водоснабжение горячее | B14: 100 | C14: 114.2 | D14: 114.2
A15: водоотведение | B15: 100 | C15: 122.3 | D15: 122.3
A16: отопление | B16: 100 | C16: 117.4 | D16: 117.4
A17: газоснабжение | B17: 100 | C17: 110.4 | D17: 110.4
A18: электроснабжение | B18: 100 | C18: 112.4 | D18: 112.4

Sheet 24
A1: Динамика стоимости фиксированного набора потребительских товаров и услуг
A3: на конец месяца
B4: Стоимость набора, рублей | C4: В % к
C5: предыдущему месяцу | D5: декабрю предыдущего года
A6: 2025 г.
A7: Январь | B7: 21964.98 | C7: 101.24 | D7: 101.24
A8: Февраль | B8: 22142.99 | C8: 100.81 | D8: 102.06
A9: Март | B9: 22600.29 | C9: 102.07 | D9: 104.17
A10: Апрель | B10: 22854.43 | C10: 101.12 | D10: 105.34
A11: Май | B11: 23116.78 | C11: 101.15 | D11: 106.55
A12: Июнь | B12: 22986.79 | C12: 99.44 | D12: 105.95
A13: Июль | B13: 23275.62 | C13: 101.26 | D13: 107.28
A14: Август | B14: 22928.37 | C14: 98.51 | D14: 105.68
A15: 2024 г.
A16: Январь | B16: 19285.65 | C16: 100.52 | D16: 100.52
A17: Февраль | B17: 19544.34 | C17: 101.34 | D17: 101.87
A18: Март | B18: 19639.66 | C18: 100.49 | D18: 102.36
A19: Апрель | B19: 19883.02 | C19: 101.24 | D19: 103.63
A20: Май | B20: 20104.85 | C20: 101.12 | D20: 104.79
A21: Июнь | B21: 20278.16 | C21: 100.86 | D21: 105.69
A22: Июль | B22: 20727.81 | C22: 102.22 | D22: 108.04
A23: Август | B23: 20620.81 | C23: 99.48 | D23: 107.48
A24: Сентябрь | B24: 20552.09 | C24: 99.67 | D24: 107.12
A25: Октябрь | B25: 20743.7 | C25: 100.93 | D25: 108.12
A26: Ноябрь | B26: 21158.66 | C26: 102 | D26: 110.28
A27: Декабрь | B27: 21466.49 | C27: 101.45 | D27: 111.89

Sheet 25
A1: Средние потребительские цены на бензин автомобильный и топливо моторное
A3: на конец месяца, рублей за литр
B4: Август 2025 г. | C4: Справочно
C5: август 2024 г. | D5: декабрь 2024 г.
A6: Бензин автомобильный | B6: 60.45 | C6: 57.38 | D6: 59.77
A7: в том числе:
A8: марки АИ-92 | B8: 57.12 | C8: 52.07 | D8: 54.03
A9: марки АИ-95 | B9: 62.92 | C9: 57.33 | D9: 59.6
A10: марки АИ-98 и выше | B10: 81.48 | C10: 76.69 | D10: 81.05
A11: Дизельное топливо | B11: 71.09 | C11: 66.74 | D11: 70.01
A12: Газовое моторное топливо | B12: 21.43 | C12: 25.94 | D12: 29.44

Sheet 26
A1: Индексы потребительских цен на бензин автомобильный и топливо моторное
A3: на конец месяца, в процентах
B4: Август 2025 г. к
B5: предыдущему месяцу | C5: декабрю 2024 г. | D5: соответствующему месяцу предыдущего года
A6: Бензин автомобильный | B6: 100.7 | C6: 105.7 | D6: 110
A7: в том числе:
A8: марки АИ-92 | B8: 100.8 | C8: 105.9 | D8: 109.9
A9: марки АИ-95 | B9: 100.6 | C9: 105.7 | D9: 109.9
A10: марки АИ-98 и выше | B10: 100.1 | C10: 101.1 | D10: 106.9
A11: Дизельное топливо | B11: 100 | C11: 101.6 | D11: 106.5
A12: Газовое моторное топливо | B12: 100 | C12: 73.2 | D12: 83

Sheet 27
A1: ИНДЕКСЫ ЦЕН И ТАРИФОВ ПРОИЗВОДИТЕЛЕЙ
A3: Динамика индексов цен производителей промышленных товаров, реализованных на внутреннем рынке
A5: на конец периода, в процентах к предыдущему периоду
B6: Всего1) | C6: В том числе по видам экономической деятельности
C7: добыча полезных ископаемых | D7: обрабатыва-ющие производства | E7: обеспечение электричес-кой энергией, газом и паром; кондициони-рование воздуха | F7: водоснаб-жение; водоотве-дение, организация сбора и утилизации отходов, деятельность по ликвидации загрязнений
A8: 2025 г.
A9: Январь | B9: 99.6 | C9: 98.7 | D9: 100 | E9: 98.7 | F9: 100.2
A10: Февраль | B10: 99.1 | C10: 98.8 | D10: 99.1 | E10: 101.9 | F10: 95.8
A11: Март | B11: 101.1 | C11: 82.9 | D11: 108.3 | E11: 101.6 | F11: 100
A12: I квартал | B12: 99.8 | C12: 80.9 | D12: 107.4 | E12: 102.2 | F12: 95.9
A13: Апрель | B13: 98.7 | C13: 93.1 | D13: 100.4 | E13: 99.1 | F13: 100
A14: Май | B14: 90.8 | C14: 89.9 | D14: 90.1 | E14: 100.1 | F14: 100
A15: Июнь | B15: 101.6 | C15: 93.7 | D15: 103.9 | E15: 100.5 | F15: 100.6
A16: II квартал | B16: 91 | C16: 78.4 | D16: 94 | E16: 99.6 | F16: 100.6
A17: Июль | B17: 102.9 | C17: 110.7 | D17: 100.4 | E17: 106.6 | F17: 110.4
A18: Август | B18: 88.7 | C18: 100 | D18: 83.7 | E18: 105.5 | F18: 100
A19: 2024 г.
A20: Январь | B20: 101.3 | C20: 106.2 | D20: 99.8 | E20: 97.5 | F20: 100.3
A21: Февраль | B21: 97.4 | C21: 97.7 | D21: 97 | E21: 100.1 | F21: 100
A22: Март | B22: 102.9 | C22: 110.1 | D22: 100.1 | E22: 104.8 | F22: 100
A23: I квартал | B23: 101.6 | C23: 114.3 | D23: 96.9 | E23: 102.2 | F23: 100.3
A24: Апрель | B24: 101.5 | C24: 103.7 | D24: 101 | E24: 97.1 | F24: 100
A25: Май | B25: 100.8 | C25: 104.7 | D25: 99.2 | E25: 100.5 | F25: 100
A26: Июнь | B26: 96 | C26: 87.5 | D26: 99.7 | E26: 99 | F26: 100
A27: II квартал | B27: 98.3 | C27: 95 | D27: 99.8 | E27: 96.6 | F27: 100
A28: Июль | B28: 102.6 | C28: 107.8 | D28: 100.4 | E28: 100.5 | F28: 110.8
A29: Август | B29: 99.4 | C29: 94.6 | D29: 101.1 | E29: 105.1 | F29: 100
A30: Сентябрь | B30: 101.6 | C30: 103.9 | D30: 100.5 | E30: 103.8 | F30: 100.6
A31: III квартал | B31: 103.7 | C31: 105.9 | D31: 102 | E31: 109.6 | F31: 111.4
... A35: IV квартал | B35: 100.5 | C35: 101.3 | D35: 100.2 | E35: 100.4 | F35: 100
A37: 1) По видам экономической деятельности «добыча полезных ископаемых», «обрабатывающие производства», «обеспечение электрической энергией, газом и паром; кондиционирование воздуха», «водоснабжение; водоотведение, организация сбора и утилизации отходов, деятельность по ликвидации загрязнений»

Sheet 28
A1: Индексы цен производителей промышленных товаров, реализованных на внутреннем рынке, по отдельным видам экономической деятельности
A3: на конец месяца, в процентах
B4: Август 2025 г. к декабрю 2024 г. | C4: Справочно
C5: август 2024 г. к декабрю 2023 г.
A6: Всего1) | B6: 82.9 | C6: 101.9
A7: Добыча полезных ископаемых | B7: 70.3 | C7: 110.6
A8: добыча нефти и природного газа | B8: 69 | C8: 109.8
A9: добыча прочих полезных ископаемых | B9: 106 | C9: 119.6
A10: Обрабатывающие производства | B10: 84.8 | C10: 98.2
A11: производство пищевых продуктов | B11: 103.7 | C11: 102.9
A12: производство напитков | B12: 114.2 | C12: 107.1
A13: производство одежды | B13: 111.1 | C13: 98.8
A14: обработка древесины и производство изделий из дерева и пробки, кроме мебели, производство изделий из соломки и материалов для плетения | B14: 95.5 | C14: 111.1
A15: производство бумаги и бумажных изделий | B15: 94.3 | C15: 107.6
A16: производство кокса и нефтепродуктов | B16: 89.6 | C16: 89.8
A17: производство химических веществ и химических продуктов | B17: 75.1 | C17: 94.9
... A27: Водоснабжение; водоотведение, организация сбора и утилизации отходов, деятельность по ликвидации загрязнений | B27: 106.6 | C27: 111.1
A29: 1) По видам экономической деятельности «добыча полезных ископаемых», «обрабатывающие производства», «обеспечение электрической энергией, газом и паром; кондиционирование воздуха», «водоснабжение; водоотведение, организация сбора и утилизации отходов, деятельность по ликвидации загрязнений»

Sheet 29
A1: Индексы цен производителей отдельных видов промышленных товаров, реализованных на внутреннем рынке
A3: на конец месяца, в процентах
B4: Август 2025 г. к
B5: предыдущему месяцу | C5: декабрю 2024 г. | D5: соответствующему месяцу предыдущего года
A6: Нефть обезвоженная, обессоленная и стабилизированная | B6: 100 | C6: 69 | D6: 72.8
A7: Говядина парная, остывшая или охлажденная | B7: 100 | C7: 117.1 | D7: 124.9
A8: Свинина парная, остывшая или охлажденная домашних свиней | B8: 101.4 | C8: 98.6 | D8: 110.2
A9: Мясо птицы охлажденное, в том числе для детского питания | B9: 100 | C9: 100.8 | D9: 100
A10: Изделия колбасные и аналогичная пищевая продукция из мяса, субпродуктов или крови животных, из мяса и субпродуктов птицы | B10: 100.3 | C10: 111.1 | D10: 115.7
A11: Молоко питьевое пастеризованное | B11: 98.9 | C11: 100.9 | D11: 119.8
A12: Мука пшеничная | B12: 100.5 | C12: 96.8 | D12: 102.2
A13: Хлеб и хлебобулочные изделия недлительного хранения | B13: 103.1 | C13: 106.8 | D13: 115.7
A14: Водка | B14: 100.1 | C14: 117.1 | D14: 117.1
A15: Пиво, кроме отходов пивоварения | B15: 100 | C15: 112.6 | D15: 118.9
A16: Бензин автомобильный | B16: 113.4 | C16: 125.5 | D16: 100.6
A17: Топливо дизельное | B17: 96.2 | C17: 82.4 | D17: 89.6
... A19: Пар и горячая вода | B19: 100 | C19: 119.7 | D19: 119.8

Sheet 30
A1: Динамика индексов цен производителей сельскохозяйственной продукции, реализованной сельскохозяйственными организациями
A3: на конец периода, в процентах к предыдущему периоду
B4: Всего | C4: В том числе на продукцию
C5: растениеводства | D5: животноводства
A6: 2025 г.
A7: Январь | B7: 102.6 | C7: 106.4 | D7: 101.4
A8: Февраль | B8: 102.3 | C8: 102.4 | D8: 102.3
A9: Март | B9: 95.7 | C9: 90.5 | D9: 97.4
A10: I квартал | B10: 100.43 | C10: 98.7 | D10: 100.98
A11: Апрель | B11: 99.5 | C11: 101.8 | D11: 98.8
A12: Май | B12: 102.1 | C12: 98.1 | D12: 103.4
A13: Июнь | B13: 98.5 | C13: 95.9 | D13: 99.3
A14: II квартал | B14: 100.1 | C14: 95.7 | D14: 101.4
A15: Июль | B15: 98.1 | C15: 94.4 | D15: 99.1
A16: Август | B16: 99 | C16: 94.8 | D16: 100.2
A17: 2024 г.
A18: Январь | B18: 104 | C18: 110.8 | D18: 102.3
A19: Февраль | B19: 98.2 | C19: 107.9 | D19: 95.6
A20: Март | B20: 95.2 | C20: 85 | D20: 98.2
A21: I квартал | B21: 97.1 | C21: 101.6 | D21: 96.1
A22: Апрель | B22: 93.9 | C22: 99.4 | D22: 92.6
A23: Май | B23: 95.8 | C23: 89.7 | D23: 97.4
A24: Июнь | B24: 98.9 | C24: 92.2 | D24: 100.5
A25: II квартал | B25: 88.9 | C25: 82.3 | D25: 90.6
A26: Июль | B26: 102.2 | C26: 108.6 | D26: 100.8
A27: Август | B27: 95.7 | C27: 89.5 | D27: 97.3
A28: Сентябрь | B28: 100 | C28: 104.2 | D28: 99.1
A29: III квартал | B29: 97.9 | C29: 101.4 | D29: 97.1
... A33: IV квартал | B33: 108.9 | C33: 132 | D33: 103.3

Sheet 31
A1: Динамика индексов цен на продукцию (затраты, услуги) инвестиционного назначения по элементам технологической структуры
A3: на конец периода, в процентах к предыдущему периоду
B4: Сводный индекс цен на продукцию (затраты, услуги) инвестиционного назначения | C4: В том числе индексы цен
C5: производителей на строительную продукцию | D5: приобретения машин и оборудования инвестиционного назначения | E5: на прочую продукцию (затраты, услуги) инвестиционного назначения
A6: 2025 г.
A7: Январь | B7: 99.9 | C7: 100.3 | D7: 99 | E7: 100.2
A8: Февраль | B8: 100 | C8: 100.1 | D8: 99.6 | E8: 100.3
A9: Март | B9: 99.6 | C9: 100.73 | D9: 98.6 | E9: 93.48
A10: I квартал | B10: 99.4 | C10: 101.2 | D10: 97.2 | E10: 94
A11: Апрель | B11: 96.7 | C11: 100.7 | D11: 88.3 | E11: 99.91
A12: Май | B12: 102.3 | C12: 100.9 | D12: 105.7 | E12: 100.4
A13: Июнь | B13: 105.2 | C13: 100.7 | D13: 115.8 | E13: 99.9
A14: II квартал | B14: 104.1 | C14: 102.4 | D14: 108.2 | E14: 100.2
A15: Июль | B15: 101.9 | C15: 100.3 | D15: 105.2 | E15: 100
A16: Август | B16: 99.7 | C16: 100.9 | D16: 97.6 | E16: 100
A17: 2024 г.
A18: Январь | B18: 98.9 | C18: 98.4 | D18: 99.6 | E18: 100
A19: Февраль | B19: 101.2 | C19: 100.2 | D19: 101.3 | E19: 108.5
A20: Март | B20: 100.2 | C20: 100.1 | D20: 100.4 | E20: 99.8
A21: I квартал | B21: 100.3 | C21: 98.7 | D21: 101.3 | E21: 108.2
A22: Апрель | B22: 100.5 | C22: 100.4 | D22: 101 | E22: 99.7
A23: Май | B23: 101.5 | C23: 100.3 | D23: 100.6 | E23: 113
A24: Июнь | B24: 100.5 | C24: 100.9 | D24: 99.8 | E24: 99.7
A25: II квартал | B25: 102.5 | C25: 101.6 | D25: 101.4 | E25: 112.4
A26: Июль | B26: 100.2 | C26: 100.4 | D26: 99.8 | E26: 100.1
A27: Август | B27: 100.4 | C27: 100.2 | D27: 101 | E27: 99.9
A28: Сентябрь | B28: 100.8 | C28: 100.5 | D28: 101.6 | E28: 100.2
A29: III квартал | B29: 101.5 | C29: 101.1 | D29: 102.4 | E29: 100.2
... A33: IV квартал | B33: 102.7 | C33: 102.4 | D33: 103.9 | E33: 101

Sheet 32
A1: Динамика индексов тарифов на грузовые перевозки отдельными видами транспорта
A3: на конец периода, в процентах к предыдущему периоду
B4: Всего | C4: В том числе транспорт
C5: автомобильный | D5: трубопроводный | E5: внутренний водный
A6: 2025 г.
A7: Январь | B7: 109.3 | C7: 103.4 | D7: 109.9 | E7: 100
A8: Февраль | B8: 100.2 | C8: 102.8 | D8: 100 | E8: 100
A9: Март | B9: 100 | C9: 100.7 | D9: 100 | E9: 100
A10: I квартал | B10: 109.5 | C10: 107.1 | D10: 109.9 | E10: 100
A11: Апрель | B11: 100 | C11: 100.7 | D11: 100 | E11: 100
A12: Май | B12: 100.2 | C12: 103 | D12: 100 | E12: 101.2
A13: Июнь | B13: 100.2 | C13: 99.9 | D13: 100 | E13: 108.9
A14: II квартал | B14: 100.4 | C14: 103.6 | D14: 100 | E14: 110.2
A15: Июль | B15: 100 | C15: 100.8 | D15: 100 | E15: 100
A16: Август | B16: 99.9 | C16: 98.6 | D16: 100 | E16: 100
A17: 2024 г.
A18: Январь | B18: 106.8 | C18: 103.6 | D18: 107.2 | E18: 100
A19: Февраль | B19: 100.1 | C19: 103.1 | D19: 100 | E19: 100
A20: Март | B20: 100 | C20: 100 | D20: 100 | E20: 100
A21: I квартал | B21: 106.9 | C21: 106.8 | D21: 107.2 | E21: 100
A22: Апрель | B22: 100 | C22: 100.1 | D22: 100 | E22: 100
A23: Май | B23: 100 | C23: 99.7 | D23: 100 | E23: 100.3
A24: Июнь | B24: 100 | C24: 100 | D24: 100 | E24: 100
A25: II квартал | B25: 100 | C25: 99.8 | D25: 100 | E25: 100.3
A26: Июль | B26: 100.3 | C26: 109.9 | D26: 100 | E26: 100
A27: Август | B27: 100 | C27: 100 | D27: 100 | E27: 100
A28: Сентябрь | B28: 100 | C28: 100 | D28: 100 | E28: 100
A29: III квартал | B29: 100.3 | C29: 109.9 | D29: 100 | E29: 100
... A33: IV квартал | B33: 100 | C33: 100.1 | D33: 100 | E33: 100

Sheet 33
A1: V. СОСТОЯНИЕ ПЛАТЕЖЕЙ И РАСЧЕТОВ В ОРГАНИЗАЦИЯХ
A2: (без субъектов малого предпринимательства)
A4: Просроченная кредиторская задолженность организаций по видам экономической деятельности в июле 2025 года
A6: на конец месяца, млн рублей
B7: Просроченная кредиторская задолженность – всего | C7: Из нее
C8: поставщикам | D8: в бюджет | E8: по платежам в государственные внебюджетные фонды
A9: Всего | B9: 71086.3 | C9: 63572.9 | D9: 101.1 | E9: 34.4
